# SOME DESCRIPTIVE TITLE.
# Copyright (C) 2001 Python Software Foundation
# This file is distributed under the same license as the Python package.
# FIRST AUTHOR <EMAIL@ADDRESS>, YEAR.
#
# Translators:
# python-doc bot, 2025
# Daniel Nylander <po@danielnylander.se>, 2025
#
#, fuzzy
msgid ""
msgstr ""
"Project-Id-Version: Python 3.14\n"
"Report-Msgid-Bugs-To: \n"
"POT-Creation-Date: 2025-08-13 14:19+0000\n"
"PO-Revision-Date: 2025-08-02 17:35+0000\n"
"Last-Translator: Daniel Nylander <po@danielnylander.se>, 2025\n"
"Language-Team: Swedish (https://app.transifex.com/python-doc/teams/5390/"
"sv/)\n"
"MIME-Version: 1.0\n"
"Content-Type: text/plain; charset=UTF-8\n"
"Content-Transfer-Encoding: 8bit\n"
"Language: sv\n"
"Plural-Forms: nplurals=2; plural=(n != 1);\n"

msgid "Errors and Exceptions"
msgstr "Fel och undantag"

msgid ""
"Until now error messages haven't been more than mentioned, but if you have "
"tried out the examples you have probably seen some.  There are (at least) "
"two distinguishable kinds of errors: *syntax errors* and *exceptions*."
msgstr ""
"Hittills har felmeddelanden inte mer än nämnts, men om du har provat "
"exemplen har du förmodligen sett några.  Det finns (minst) två typer av fel "
"som kan särskiljas: *syntaxfel* och *undantag*."

msgid "Syntax Errors"
msgstr "Syntaxfel"

msgid ""
"Syntax errors, also known as parsing errors, are perhaps the most common "
"kind of complaint you get while you are still learning Python::"
msgstr ""
"Syntaxfel, även kända som parsingfel, är kanske den vanligaste typen av "
"klagomål du får medan du fortfarande lär dig Python::"

msgid ""
">>> while True print('Hello world')\n"
"  File \"<stdin>\", line 1\n"
"    while True print('Hello world')\n"
"               ^^^^^\n"
"SyntaxError: invalid syntax"
msgstr ""
"&gt;&gt;&gt; while True print('Hello world')\n"
"  Fil \"<stdin>\", rad 1\n"
"    while True print('Hej världen')\n"
"               ^^^^^\n"
"SyntaxError: ogiltig syntax"

msgid ""
"The parser repeats the offending line and displays little arrows pointing at "
"the place where the error was detected.  Note that this is not always the "
"place that needs to be fixed.  In the example, the error is detected at the "
"function :func:`print`, since a colon (``':'``) is missing just before it."
msgstr ""
"Parsern upprepar den felaktiga raden och visar små pilar som pekar på den "
"plats där felet upptäcktes.  Observera att detta inte alltid är den plats "
"som behöver åtgärdas.  I exemplet upptäcks felet vid funktionen :func:"
"`print`, eftersom det saknas ett kolon (``':'``) precis före den."

msgid ""
"The file name (``<stdin>`` in our example) and line number are printed so "
"you know where to look in case the input came from a file."
msgstr ""
"Filnamnet (``<stdin>`` i vårt exempel) och radnumret skrivs ut så att du vet "
"var du ska leta om indata kom från en fil."

msgid "Exceptions"
msgstr "Undantag"

msgid ""
"Even if a statement or expression is syntactically correct, it may cause an "
"error when an attempt is made to execute it. Errors detected during "
"execution are called *exceptions* and are not unconditionally fatal: you "
"will soon learn how to handle them in Python programs.  Most exceptions are "
"not handled by programs, however, and result in error messages as shown "
"here::"
msgstr ""
"Även om en sats eller ett uttryck är syntaktiskt korrekt kan det orsaka ett "
"fel när man försöker exekvera det. Fel som upptäcks under exekveringen "
"kallas *undantag* och är inte ovillkorligen fatala: du kommer snart att lära "
"dig hur du hanterar dem i Python-program.  De flesta undantag hanteras dock "
"inte av program, utan resulterar i felmeddelanden som visas här::"

msgid ""
">>> 10 * (1/0)\n"
"Traceback (most recent call last):\n"
"  File \"<stdin>\", line 1, in <module>\n"
"    10 * (1/0)\n"
"          ~^~\n"
"ZeroDivisionError: division by zero\n"
">>> 4 + spam*3\n"
"Traceback (most recent call last):\n"
"  File \"<stdin>\", line 1, in <module>\n"
"    4 + spam*3\n"
"        ^^^^\n"
"NameError: name 'spam' is not defined\n"
">>> '2' + 2\n"
"Traceback (most recent call last):\n"
"  File \"<stdin>\", line 1, in <module>\n"
"    '2' + 2\n"
"    ~~~~^~~\n"
"TypeError: can only concatenate str (not \"int\") to str"
msgstr ""
"&gt;&gt;&gt; 10 * (1/0)\n"
"Traceback (senaste anropet senast):\n"
"  Fil \"<stdin>\", rad 1, i <module>\n"
"    10 * (1/0)\n"
"          ~^~\n"
"ZeroDivisionError: division med noll\n"
"&gt;&gt;&gt; 4 + spam*3\n"
"Traceback (senaste anropet senast):\n"
"  Fil \"<stdin>\", rad 1, i <module>\n"
"    4 + skräppost*3\n"
"        ^^^^\n"
"NameError: namnet 'spam' är inte definierat\n"
"&gt;&gt;&gt; '2' + 2\n"
"Traceback (senaste anropet senast):\n"
"  Fil \"<stdin>\", rad 1, i <module>\n"
"    '2' + 2\n"
"    ~~~~^~~\n"
"TypeError: kan bara konkatenera str (inte \"int\") till str"

msgid ""
"The last line of the error message indicates what happened. Exceptions come "
"in different types, and the type is printed as part of the message: the "
"types in the example are :exc:`ZeroDivisionError`, :exc:`NameError` and :exc:"
"`TypeError`. The string printed as the exception type is the name of the "
"built-in exception that occurred.  This is true for all built-in exceptions, "
"but need not be true for user-defined exceptions (although it is a useful "
"convention). Standard exception names are built-in identifiers (not reserved "
"keywords)."
msgstr ""
"Den sista raden i felmeddelandet anger vad som hände. Undantag finns i olika "
"typer och typen skrivs ut som en del av meddelandet: typerna i exemplet är :"
"exc:`ZeroDivisionError`, :exc:`NameError` och :exc:`TypeError`. Den sträng "
"som skrivs ut som undantagstyp är namnet på det inbyggda undantag som "
"inträffade.  Detta gäller för alla inbyggda undantag, men behöver inte gälla "
"för användardefinierade undantag (även om det är en användbar konvention). "
"Standardnamn på undantag är inbyggda identifierare (inte reserverade "
"nyckelord)."

msgid ""
"The rest of the line provides detail based on the type of exception and what "
"caused it."
msgstr ""
"Resten av raden innehåller detaljer som baseras på typen av undantag och vad "
"som orsakade det."

msgid ""
"The preceding part of the error message shows the context where the "
"exception occurred, in the form of a stack traceback. In general it contains "
"a stack traceback listing source lines; however, it will not display lines "
"read from standard input."
msgstr ""
"Den föregående delen av felmeddelandet visar det sammanhang där undantaget "
"inträffade, i form av en stack traceback. I allmänhet innehåller det en "
"stack traceback som listar källrader, men det kommer inte att visa rader som "
"läses från standardinmatningen."

msgid ""
":ref:`bltin-exceptions` lists the built-in exceptions and their meanings."
msgstr ""
":ref:`bltin-exceptions` listar de inbyggda undantagen och deras innebörd."

msgid "Handling Exceptions"
msgstr "Hantering av undantag"

msgid ""
"It is possible to write programs that handle selected exceptions. Look at "
"the following example, which asks the user for input until a valid integer "
"has been entered, but allows the user to interrupt the program (using :kbd:"
"`Control-C` or whatever the operating system supports); note that a user-"
"generated interruption is signalled by raising the :exc:`KeyboardInterrupt` "
"exception. ::"
msgstr ""
"Det är möjligt att skriva program som hanterar utvalda undantag. Titta på "
"följande exempel, som ber användaren om inmatning tills ett giltigt heltal "
"har matats in, men tillåter användaren att avbryta programmet (med hjälp av :"
"kbd:`Control-C` eller vad operativsystemet stöder); notera att ett "
"användargenererat avbrott signaleras genom att lyfta :exc:"
"`KeyboardInterrupt` undantaget. ::"

msgid ""
">>> while True:\n"
"...     try:\n"
"...         x = int(input(\"Please enter a number: \"))\n"
"...         break\n"
"...     except ValueError:\n"
"...         print(\"Oops!  That was no valid number.  Try again...\")\n"
"..."
msgstr ""
">>> while True:\n"
"... försök:\n"
"... x = int(input(\"Vänligen ange ett nummer: \"))\n"
"... break\n"
"... förutom ValueError:\n"
"... print(\"Hoppsan! Det var inget giltigt tal. Försök igen ...\")\n"
"..."

msgid "The :keyword:`try` statement works as follows."
msgstr "Satsen :keyword:`try` fungerar på följande sätt."

msgid ""
"First, the *try clause* (the statement(s) between the :keyword:`try` and :"
"keyword:`except` keywords) is executed."
msgstr ""
"Först utförs *försöksklausulen* (satsen eller satserna mellan nyckelorden :"
"keyword:`try` och :keyword:`except`)."

msgid ""
"If no exception occurs, the *except clause* is skipped and execution of the :"
"keyword:`try` statement is finished."
msgstr ""
"Om inget undantag inträffar hoppas *except-klausulen* över och körningen av :"
"keyword:`try`-satsen avslutas."

msgid ""
"If an exception occurs during execution of the :keyword:`try` clause, the "
"rest of the clause is skipped.  Then, if its type matches the exception "
"named after the :keyword:`except` keyword, the *except clause* is executed, "
"and then execution continues after the try/except block."
msgstr ""
"Om ett undantag inträffar under exekveringen av :keyword:`try`-satsen, "
"hoppas resten av satsen över.  Om dess typ matchar undantaget som anges "
"efter nyckelordet :keyword:`except`, exekveras *except-satsen*, och sedan "
"fortsätter exekveringen efter try/except-blocket."

msgid ""
"If an exception occurs which does not match the exception named in the "
"*except clause*, it is passed on to outer :keyword:`try` statements; if no "
"handler is found, it is an *unhandled exception* and execution stops with an "
"error message."
msgstr ""
"Om ett undantag inträffar som inte stämmer överens med undantaget som anges "
"i *except-satsen*, skickas det vidare till yttre :keyword:`try`-satser; om "
"ingen hanterare hittas är det ett *ohanterat undantag* och exekveringen "
"stoppas med ett felmeddelande."

msgid ""
"A :keyword:`try` statement may have more than one *except clause*, to "
"specify handlers for different exceptions.  At most one handler will be "
"executed. Handlers only handle exceptions that occur in the corresponding "
"*try clause*, not in other handlers of the same :keyword:`!try` statement.  "
"An *except clause* may name multiple exceptions as a parenthesized tuple, "
"for example::"
msgstr ""
"En :keyword:`try`-sats kan ha mer än en *except-klausul* för att ange "
"hanterare för olika undantag.  Högst en hanterare kommer att exekveras. "
"Hanterarna hanterar bara undantag som förekommer i motsvarande *try-sats*, "
"inte i andra hanterare av samma :keyword:`!try`-sats.  En *except-sats* kan "
"namnge flera undantag som en parentesförsedd tupel, till exempel::"

msgid ""
"... except (RuntimeError, TypeError, NameError):\n"
"...     pass"
msgstr ""
"... utom (RuntimeError, TypeError, NameError):\n"
"... pass"

msgid ""
"A class in an :keyword:`except` clause matches exceptions which are "
"instances of the class itself or one of its derived classes (but not the "
"other way around --- an *except clause* listing a derived class does not "
"match instances of its base classes). For example, the following code will "
"print B, C, D in that order::"
msgstr ""
"En klass i en :keyword:`except`-sats matchar undantag som är instanser av "
"klassen själv eller en av dess härledda klasser (men inte tvärtom --- en "
"*except-sats* som listar en härledd klass matchar inte instanser av dess "
"basklasser). Till exempel kommer följande kod att skriva ut B, C, D i den "
"ordningen::"

msgid ""
"class B(Exception):\n"
"    pass\n"
"\n"
"class C(B):\n"
"    pass\n"
"\n"
"class D(C):\n"
"    pass\n"
"\n"
"for cls in [B, C, D]:\n"
"    try:\n"
"        raise cls()\n"
"    except D:\n"
"        print(\"D\")\n"
"    except C:\n"
"        print(\"C\")\n"
"    except B:\n"
"        print(\"B\")"
msgstr ""
"klass B(Undantag):\n"
"    pass\n"
"\n"
"klass C(B):\n"
"    pass\n"
"\n"
"klass D(C):\n"
"    godkänd\n"
"\n"
"för cls i [B, C, D]:\n"
"    try:\n"
"        raise cls()\n"
"    utom D:\n"
"        print(\"D\")\n"
"    except C:\n"
"        print(\"C\")\n"
"    utom B:\n"
"        print(\"B\")"

msgid ""
"Note that if the *except clauses* were reversed (with ``except B`` first), "
"it would have printed B, B, B --- the first matching *except clause* is "
"triggered."
msgstr ""
"Observera att om *except-klausulerna* hade varit omvända (med ``except B`` "
"först), skulle det ha skrivit ut B, B, B --- den första matchande *except-"
"klausulen* utlöses."

msgid ""
"When an exception occurs, it may have associated values, also known as the "
"exception's *arguments*. The presence and types of the arguments depend on "
"the exception type."
msgstr ""
"När ett undantag inträffar kan det ha associerade värden, även kallade "
"undantagets *argument*. Vilka argument som finns och vilka typer av argument "
"som finns beror på undantagstypen."

msgid ""
"The *except clause* may specify a variable after the exception name.  The "
"variable is bound to the exception instance which typically has an ``args`` "
"attribute that stores the arguments. For convenience, builtin exception "
"types define :meth:`~object.__str__` to print all the arguments without "
"explicitly accessing ``.args``.  ::"
msgstr ""
"I *except-klausulen* kan en variabel anges efter undantagsnamnet.  Variabeln "
"är bunden till undantagsinstansen som vanligtvis har ett ``args``-attribut "
"som lagrar argumenten. För enkelhetens skull definierar inbyggda "
"undantagstyper :meth:`~object.__str__` för att skriva ut alla argument utan "
"att explicit komma åt ``.args``. ::"

msgid ""
">>> try:\n"
"...     raise Exception('spam', 'eggs')\n"
"... except Exception as inst:\n"
"...     print(type(inst))    # the exception type\n"
"...     print(inst.args)     # arguments stored in .args\n"
"...     print(inst)          # __str__ allows args to be printed directly,\n"
"...                          # but may be overridden in exception "
"subclasses\n"
"...     x, y = inst.args     # unpack args\n"
"...     print('x =', x)\n"
"...     print('y =', y)\n"
"...\n"
"<class 'Exception'>\n"
"('spam', 'eggs')\n"
"('spam', 'eggs')\n"
"x = spam\n"
"y = eggs"
msgstr ""
">>> försök:\n"
"... raise Exception('spam', 'ägg')\n"
"... except Exception as inst:\n"
"... print(type(inst))    # undantagstypen\n"
"... print(inst.args) # argument lagrade i .args\n"
"... print(inst) # __str__ gör att args kan skrivas ut direkt,\n"
"...                          # men kan åsidosättas i undantagssubklasser\n"
"... x, y = inst.args # packa upp args\n"
"... print('x =', x)\n"
"... print('y =', y)\n"
"...\n"
"<klass 'Undantag'>\n"
"('spam', 'ägg')\n"
"('skräppost', 'ägg')\n"
"x = skräppost\n"
"y = ägg"

msgid ""
"The exception's :meth:`~object.__str__` output is printed as the last part "
"('detail') of the message for unhandled exceptions."
msgstr ""
"Undantagets :meth:`~object.__str__`-utdata skrivs ut som den sista delen "
"(\"detail\") av meddelandet för ohanterade undantag."

msgid ""
":exc:`BaseException` is the common base class of all exceptions. One of its "
"subclasses, :exc:`Exception`, is the base class of all the non-fatal "
"exceptions. Exceptions which are not subclasses of :exc:`Exception` are not "
"typically handled, because they are used to indicate that the program should "
"terminate. They include :exc:`SystemExit` which is raised by :meth:`sys."
"exit` and :exc:`KeyboardInterrupt` which is raised when a user wishes to "
"interrupt the program."
msgstr ""
":exc:`BaseException` är den gemensamma basklassen för alla undantag. En av "
"dess underklasser, :exc:`Exception`, är basklassen för alla icke-fatal "
"undantag. Undantag som inte är underklasser till :exc:`Exception` hanteras "
"normalt inte, eftersom de används för att ange att programmet ska avslutas. "
"De inkluderar :exc:`SystemExit` som utlöses av :meth:`sys.exit` och :exc:"
"`KeyboardInterrupt` som utlöses när en användare vill avbryta programmet."

msgid ""
":exc:`Exception` can be used as a wildcard that catches (almost) everything. "
"However, it is good practice to be as specific as possible with the types of "
"exceptions that we intend to handle, and to allow any unexpected exceptions "
"to propagate on."
msgstr ""
":exc:`Exception` kan användas som ett jokertecken som fångar upp (nästan) "
"allt. Det är dock god praxis att vara så specifik som möjligt med de typer "
"av undantag som vi avser att hantera, och att låta oväntade undantag sprida "
"sig vidare."

msgid ""
"The most common pattern for handling :exc:`Exception` is to print or log the "
"exception and then re-raise it (allowing a caller to handle the exception as "
"well)::"
msgstr ""
"Det vanligaste mönstret för att hantera :exc:`Exception` är att skriva ut "
"eller logga undantaget och sedan höja det igen (så att en anropare också kan "
"hantera undantaget)::"

msgid ""
"import sys\n"
"\n"
"try:\n"
"    f = open('myfile.txt')\n"
"    s = f.readline()\n"
"    i = int(s.strip())\n"
"except OSError as err:\n"
"    print(\"OS error:\", err)\n"
"except ValueError:\n"
"    print(\"Could not convert data to an integer.\")\n"
"except Exception as err:\n"
"    print(f\"Unexpected {err=}, {type(err)=}\")\n"
"    raise"
msgstr ""
"import sys\n"
"\n"
"try:\n"
"    f = open('myfile.txt')\n"
"    s = f.readline()\n"
"    i = int(s.strip())\n"
"except OSError as err:\n"
"    print(\"OS error:\", err)\n"
"except ValueError:\n"
"    print(\"Could not convert data to an integer.\")\n"
"except Exception as err:\n"
"    print(f\"Unexpected {err=}, {type(err)=}\")\n"
"    raise"

msgid ""
"The :keyword:`try` ... :keyword:`except` statement has an optional *else "
"clause*, which, when present, must follow all *except clauses*.  It is "
"useful for code that must be executed if the *try clause* does not raise an "
"exception. For example::"
msgstr ""
"Satsen :keyword:`try` ... :keyword:`except` har en valfri *else-klausul* "
"som, när den finns, måste följa efter alla *except-klausuler*.  Den är "
"användbar för kod som måste köras om *try-satsen* inte ger upphov till ett "
"undantag. Till exempel::"

msgid ""
"for arg in sys.argv[1:]:\n"
"    try:\n"
"        f = open(arg, 'r')\n"
"    except OSError:\n"
"        print('cannot open', arg)\n"
"    else:\n"
"        print(arg, 'has', len(f.readlines()), 'lines')\n"
"        f.close()"
msgstr ""
"för arg i sys.argv[1:]:\n"
"    try:\n"
"        f = open(arg, 'r')\n"
"    except OSError:\n"
"        print('kan inte öppna', arg)\n"
"    else:\n"
"        print(arg, 'har', len(f.readlines()), 'rader')\n"
"        f.close()"

msgid ""
"The use of the :keyword:`!else` clause is better than adding additional code "
"to the :keyword:`try` clause because it avoids accidentally catching an "
"exception that wasn't raised by the code being protected by the :keyword:`!"
"try` ... :keyword:`!except` statement."
msgstr ""
"Användningen av :keyword:`!else`-satsen är bättre än att lägga till "
"ytterligare kod till :keyword:`try`-satsen eftersom den undviker att av "
"misstag fånga ett undantag som inte uppstod av koden som skyddas av :keyword:"
"`!try` ... :keyword:`!except`-satsen."

msgid ""
"Exception handlers do not handle only exceptions that occur immediately in "
"the *try clause*, but also those that occur inside functions that are called "
"(even indirectly) in the *try clause*. For example::"
msgstr ""
"Undantagshanterare hanterar inte bara undantag som inträffar direkt i "
"*försökssatsen*, utan även de som inträffar inuti funktioner som anropas "
"(även indirekt) i *försökssatsen*. Till exempel::"

msgid ""
">>> def this_fails():\n"
"...     x = 1/0\n"
"...\n"
">>> try:\n"
"...     this_fails()\n"
"... except ZeroDivisionError as err:\n"
"...     print('Handling run-time error:', err)\n"
"...\n"
"Handling run-time error: division by zero"
msgstr ""
">>> def this_fails():\n"
"... x = 1/0\n"
"...\n"
">>> försök:\n"
"... this_fails()\n"
"... except ZeroDivisionError as err:\n"
"... print('Hantering av körtidsfel:', err)\n"
"...\n"
"Hantering av körtidsfel: division med noll"

msgid "Raising Exceptions"
msgstr "Utredning av undantag"

msgid ""
"The :keyword:`raise` statement allows the programmer to force a specified "
"exception to occur. For example::"
msgstr ""
"Med :keyword:`raise` kan programmeraren tvinga ett specificerat undantag att "
"inträffa. Till exempel::"

msgid ""
">>> raise NameError('HiThere')\n"
"Traceback (most recent call last):\n"
"  File \"<stdin>\", line 1, in <module>\n"
"    raise NameError('HiThere')\n"
"NameError: HiThere"
msgstr ""
"&gt;&gt;&gt; höja NamnFel('HiThere')\n"
"Traceback (senaste anropet senast):\n"
"  Fil \"<stdin>\", rad 1, i <module>\n"
"    raise Namnfel('HiThere')\n"
"NamnFel: HiThere"

msgid ""
"The sole argument to :keyword:`raise` indicates the exception to be raised. "
"This must be either an exception instance or an exception class (a class "
"that derives from :class:`BaseException`, such as :exc:`Exception` or one of "
"its subclasses).  If an exception class is passed, it will be implicitly "
"instantiated by calling its constructor with no arguments::"
msgstr ""
"Det enda argumentet till :keyword:`raise` anger det undantag som skall tas "
"upp. Detta måste vara antingen en undantagsinstans eller en undantagsklass "
"(en klass som härstammar från :class:`BaseException`, t.ex. :exc:`Exception` "
"eller en av dess underklasser).  Om en undantagsklass skickas, kommer den "
"att instansieras implicit genom att anropa dess konstruktör utan argument::"

msgid "raise ValueError  # shorthand for 'raise ValueError()'"
msgstr "raise ValueError # förkortning för \"raise ValueError()"

msgid ""
"If you need to determine whether an exception was raised but don't intend to "
"handle it, a simpler form of the :keyword:`raise` statement allows you to re-"
"raise the exception::"
msgstr ""
"Om du behöver avgöra om ett undantag har uppstått, men inte tänker hantera "
"det, kan du använda en enklare form av :keyword:`raise` för att upprepa "
"undantaget::"

msgid ""
">>> try:\n"
"...     raise NameError('HiThere')\n"
"... except NameError:\n"
"...     print('An exception flew by!')\n"
"...     raise\n"
"...\n"
"An exception flew by!\n"
"Traceback (most recent call last):\n"
"  File \"<stdin>\", line 2, in <module>\n"
"    raise NameError('HiThere')\n"
"NameError: HiThere"
msgstr ""
"&gt;&gt;&gt; försök:\n"
"... raise NameError('HiThere')\n"
"... förutom NameError:\n"
"... print('Ett undantag flög förbi!')\n"
"... raise\n"
"...\n"
"Ett undantag flög förbi!\n"
"Traceback (senaste anropet senast):\n"
"  Fil \"<stdin>\", rad 2, i <module>\n"
"    raise NamnFel('HiThere')\n"
"NamnFel: HiThere"

msgid "Exception Chaining"
msgstr "Kedjning av undantag"

msgid ""
"If an unhandled exception occurs inside an :keyword:`except` section, it "
"will have the exception being handled attached to it and included in the "
"error message::"
msgstr ""
"Om ett ohanterat undantag inträffar i ett avsnitt med :keyword:`except`, "
"kommer det undantag som hanteras att kopplas till det och inkluderas i "
"felmeddelandet::"

msgid ""
">>> try:\n"
"...     open(\"database.sqlite\")\n"
"... except OSError:\n"
"...     raise RuntimeError(\"unable to handle error\")\n"
"...\n"
"Traceback (most recent call last):\n"
"  File \"<stdin>\", line 2, in <module>\n"
"    open(\"database.sqlite\")\n"
"    ~~~~^^^^^^^^^^^^^^^^^^^\n"
"FileNotFoundError: [Errno 2] No such file or directory: 'database.sqlite'\n"
"\n"
"During handling of the above exception, another exception occurred:\n"
"\n"
"Traceback (most recent call last):\n"
"  File \"<stdin>\", line 4, in <module>\n"
"    raise RuntimeError(\"unable to handle error\")\n"
"RuntimeError: unable to handle error"
msgstr ""
"&gt;&gt;&gt; försök:\n"
"... open(\"databas.sqlite\")\n"
"... utom OSError:\n"
"... raise RuntimeError(\"det går inte att hantera felet\")\n"
"...\n"
"Traceback (senaste anropet senast):\n"
"  Fil \"<stdin>\", rad 2, i <module>\n"
"    open(\"databas.sqlite\")\n"
"    ~~~~^^^^^^^^^^^^^^^^^^^\n"
"FileNotFoundError: [Errno 2] Ingen sådan fil eller katalog: 'database."
"sqlite'\n"
"\n"
"Under hanteringen av ovanstående undantag inträffade ett annat undantag:\n"
"\n"
"Traceback (senaste anropet sist):\n"
"  Fil \"<stdin>\", rad 4, i <module>\n"
"    raise RuntimeError(\"det gick inte att hantera felet\")\n"
"RuntimeError: det gick inte att hantera felet"

msgid ""
"To indicate that an exception is a direct consequence of another, the :"
"keyword:`raise` statement allows an optional :keyword:`from<raise>` clause::"
msgstr ""
"För att indikera att ett undantag är en direkt följd av ett annat, tillåter :"
"keyword:`raise`-satsen en valfri :keyword:`from<raise>`-klausul::"

msgid ""
"# exc must be exception instance or None.\n"
"raise RuntimeError from exc"
msgstr ""
"# exc måste vara en undantagsinstans eller None.\n"
"raise RuntimeError från exc"

msgid "This can be useful when you are transforming exceptions. For example::"
msgstr ""
"Detta kan vara användbart när du transformerar undantag. Till exempel::"

msgid ""
">>> def func():\n"
"...     raise ConnectionError\n"
"...\n"
">>> try:\n"
"...     func()\n"
"... except ConnectionError as exc:\n"
"...     raise RuntimeError('Failed to open database') from exc\n"
"...\n"
"Traceback (most recent call last):\n"
"  File \"<stdin>\", line 2, in <module>\n"
"    func()\n"
"    ~~~~^^\n"
"  File \"<stdin>\", line 2, in func\n"
"ConnectionError\n"
"\n"
"The above exception was the direct cause of the following exception:\n"
"\n"
"Traceback (most recent call last):\n"
"  File \"<stdin>\", line 4, in <module>\n"
"    raise RuntimeError('Failed to open database') from exc\n"
"RuntimeError: Failed to open database"
msgstr ""
"&gt;&gt;&gt; def func():\n"
"... raise ConnectionError\n"
"...\n"
"&gt;&gt;&gt; försök:\n"
"... func()\n"
"... except ConnectionError as exc:\n"
"... raise RuntimeError('Misslyckades med att öppna databasen') from exc\n"
"...\n"
"Traceback (senaste anropet senast):\n"
"  Fil \"<stdin>\", rad 2, i <module>\n"
"    func()\n"
"    ~~~~^^\n"
"  Fil \"<stdin>\", rad 2, i func\n"
"Anslutningsfel\n"
"\n"
"Ovanstående undantag var den direkta orsaken till följande undantag:\n"
"\n"
"Traceback (senaste anropet sist):\n"
"  Fil \"<stdin>\", rad 4, i <module>\n"
"    raise RuntimeError('Misslyckades med att öppna databasen') från exc\n"
"RuntimeError (Körtidsfel): Misslyckades med att öppna databasen"

msgid ""
"It also allows disabling automatic exception chaining using the ``from "
"None`` idiom::"
msgstr ""
"Det gör det också möjligt att inaktivera automatisk undantagskedja med hjälp "
"av idiomet ``from None``::"

msgid ""
">>> try:\n"
"...     open('database.sqlite')\n"
"... except OSError:\n"
"...     raise RuntimeError from None\n"
"...\n"
"Traceback (most recent call last):\n"
"  File \"<stdin>\", line 4, in <module>\n"
"    raise RuntimeError from None\n"
"RuntimeError"
msgstr ""
"&gt;&gt;&gt; försök:\n"
"... open('database.sqlite')\n"
"... utom OSError:\n"
"... raise RuntimeError från None\n"
"...\n"
"Traceback (senaste anropet senast):\n"
"  Fil \"<stdin>\", rad 4, i <module>\n"
"    raise RuntimeError från Ingen\n"
"RuntimeFel"

msgid ""
"For more information about chaining mechanics, see :ref:`bltin-exceptions`."
msgstr "För mer information om kedjemekanik, se :ref:`bltin-exceptions`."

msgid "User-defined Exceptions"
msgstr "Användardefinierade undantag"

msgid ""
"Programs may name their own exceptions by creating a new exception class "
"(see :ref:`tut-classes` for more about Python classes).  Exceptions should "
"typically be derived from the :exc:`Exception` class, either directly or "
"indirectly."
msgstr ""
"Program kan namnge sina egna undantag genom att skapa en ny undantagsklass "
"(se :ref:`tut-classes` för mer information om Python-klasser).  Undantag bör "
"typiskt härledas från klassen :exc:`Exception`, antingen direkt eller "
"indirekt."

msgid ""
"Exception classes can be defined which do anything any other class can do, "
"but are usually kept simple, often only offering a number of attributes that "
"allow information about the error to be extracted by handlers for the "
"exception."
msgstr ""
"Undantagsklasser kan definieras som gör allt som andra klasser kan göra, men "
"de är vanligtvis enkla och erbjuder ofta bara ett antal attribut som gör att "
"information om felet kan extraheras av hanterare för undantaget."

msgid ""
"Most exceptions are defined with names that end in \"Error\", similar to the "
"naming of the standard exceptions."
msgstr ""
"De flesta undantag definieras med namn som slutar på \"Error\", vilket "
"liknar namngivningen av standardundantagen."

msgid ""
"Many standard modules define their own exceptions to report errors that may "
"occur in functions they define."
msgstr ""
"Många standardmoduler definierar sina egna undantag för att rapportera fel "
"som kan uppstå i funktioner som de definierar."

msgid "Defining Clean-up Actions"
msgstr "Definiera saneringsåtgärder"

msgid ""
"The :keyword:`try` statement has another optional clause which is intended "
"to define clean-up actions that must be executed under all circumstances.  "
"For example::"
msgstr ""
"Satsen :keyword:`try` har en annan valfri klausul som är avsedd att "
"definiera rensningsåtgärder som måste utföras under alla omständigheter.  "
"Till exempel::"

msgid ""
">>> try:\n"
"...     raise KeyboardInterrupt\n"
"... finally:\n"
"...     print('Goodbye, world!')\n"
"...\n"
"Goodbye, world!\n"
"Traceback (most recent call last):\n"
"  File \"<stdin>\", line 2, in <module>\n"
"    raise KeyboardInterrupt\n"
"KeyboardInterrupt"
msgstr ""
"&gt;&gt;&gt; försök:\n"
"... raise KeyboardInterrupt\n"
"... slutligen:\n"
"... print('Adjö, världen!')\n"
"...\n"
"Adjö, världen!\n"
"Traceback (senaste anropet senast):\n"
"  Fil \"<stdin>\", rad 2, i <module>\n"
"    raise KeyboardInterrupt (tangentbordsavbrott)\n"
"KeyboardInterrupt"

msgid ""
"If a :keyword:`finally` clause is present, the :keyword:`!finally` clause "
"will execute as the last task before the :keyword:`try` statement completes. "
"The :keyword:`!finally` clause runs whether or not the :keyword:`!try` "
"statement produces an exception. The following points discuss more complex "
"cases when an exception occurs:"
msgstr ""
"Om en :keyword:`finally`-klausul finns, kommer :keyword:`!finally`-klausulen "
"att utföras som den sista uppgiften innan :keyword:`try`-satsen avslutas. "
"Klausulen :keyword:`!finally` körs oavsett om satsen :keyword:`!try` ger "
"upphov till ett undantag eller inte. I följande punkter diskuteras mer "
"komplexa fall när ett undantag inträffar:"

msgid ""
"If an exception occurs during execution of the :keyword:`!try` clause, the "
"exception may be handled by an :keyword:`except` clause. If the exception is "
"not handled by an :keyword:`!except` clause, the exception is re-raised "
"after the :keyword:`!finally` clause has been executed."
msgstr ""
"Om ett undantag inträffar under exekveringen av :keyword:`!try`-satsen, kan "
"undantaget hanteras av en :keyword:`except`-sats. Om undantaget inte "
"hanteras av en :keyword:`!except`-sats, kommer undantaget att tas upp igen "
"efter att :keyword:`!finally`-satsen har exekverats."

msgid ""
"An exception could occur during execution of an :keyword:`!except` or :"
"keyword:`!else` clause. Again, the exception is re-raised after the :keyword:"
"`!finally` clause has been executed."
msgstr ""
"Ett undantag kan inträffa under exekvering av en :keyword:`!except` eller :"
"keyword:`!else` klausul. Återigen, undantaget tas upp igen efter att :"
"keyword:`!finally`-satsen har exekverats."

msgid ""
"If the :keyword:`!finally` clause executes a :keyword:`break`, :keyword:"
"`continue` or :keyword:`return` statement, exceptions are not re-raised. "
"This can be confusing and is therefore discouraged. From version 3.14 the "
"compiler emits a :exc:`SyntaxWarning` for it (see :pep:`765`)."
msgstr ""
"Om :keyword:`!finally`-satsen exekverar en :keyword:`break`-, :keyword:"
"`continue`- eller :keyword:`return`-sats, aktiveras inte undantag på nytt. "
"Detta kan vara förvirrande och avrådes därför. Från och med version 3.14 "
"skickar kompilatorn ut en :exc:`SyntaxWarning` för detta (se :pep:`765`)."

msgid ""
"If the :keyword:`!try` statement reaches a :keyword:`break`, :keyword:"
"`continue` or :keyword:`return` statement, the :keyword:`!finally` clause "
"will execute just prior to the :keyword:`!break`, :keyword:`!continue` or :"
"keyword:`!return` statement's execution."
msgstr ""
"Om :keyword:`!try`-satsen når en :keyword:`break`-, :keyword:`continue`- "
"eller :keyword:`return`-sats, kommer :keyword:`!finally`-satsen att "
"exekveras strax före :keyword:`!break`-, :keyword:`!continue`- eller :"
"keyword:`!return`-satsens exekvering."

msgid ""
"If a :keyword:`!finally` clause includes a :keyword:`!return` statement, the "
"returned value will be the one from the :keyword:`!finally` clause's :"
"keyword:`!return` statement, not the value from the :keyword:`!try` "
"clause's :keyword:`!return` statement. This can be confusing and is "
"therefore discouraged. From version 3.14 the compiler emits a :exc:"
"`SyntaxWarning` for it (see :pep:`765`)."
msgstr ""
"Om en :keyword:`!finally`-sats innehåller en :keyword:`!return`-sats, kommer "
"det returnerade värdet att vara det från :keyword:`!finally`-satsens :"
"keyword:`!return`-sats, inte värdet från :keyword:`!try`-satsens :keyword:`!"
"return`-sats. Detta kan vara förvirrande och avrådes därför. Från version "
"3.14 ger kompilatorn ut en :exc:`SyntaxWarning` för detta (se :pep:`765`)."

msgid "For example::"
msgstr "Till exempel::"

msgid ""
">>> def bool_return():\n"
"...     try:\n"
"...         return True\n"
"...     finally:\n"
"...         return False\n"
"...\n"
">>> bool_return()\n"
"False"
msgstr ""
">>> def bool_return():\n"
"... försök:\n"
"... returnera True\n"
"... finally:\n"
"... returnera False\n"
"...\n"
">>> bool_return()\n"
"Falsk"

msgid "A more complicated example::"
msgstr "Ett mer komplicerat exempel::"

msgid ""
">>> def divide(x, y):\n"
"...     try:\n"
"...         result = x / y\n"
"...     except ZeroDivisionError:\n"
"...         print(\"division by zero!\")\n"
"...     else:\n"
"...         print(\"result is\", result)\n"
"...     finally:\n"
"...         print(\"executing finally clause\")\n"
"...\n"
">>> divide(2, 1)\n"
"result is 2.0\n"
"executing finally clause\n"
">>> divide(2, 0)\n"
"division by zero!\n"
"executing finally clause\n"
">>> divide(\"2\", \"1\")\n"
"executing finally clause\n"
"Traceback (most recent call last):\n"
"  File \"<stdin>\", line 1, in <module>\n"
"    divide(\"2\", \"1\")\n"
"    ~~~~~~^^^^^^^^^^\n"
"  File \"<stdin>\", line 3, in divide\n"
"    result = x / y\n"
"             ~~^~~\n"
"TypeError: unsupported operand type(s) for /: 'str' and 'str'"
msgstr ""
"&gt;&gt;&gt; def divide(x, y):\n"
"... försök:\n"
"... resultat = x / y\n"
"... utom ZeroDivisionError:\n"
"... print(\"division med noll!\")\n"
"... annars:\n"
"... print(\"resultatet är\", resultat)\n"
"... slutligen:\n"
"... print(\"Exekvering av finally-sats\")\n"
"...\n"
"&gt;&gt;&gt; dividera(2, 1)\n"
"resultatet är 2,0\n"
"exekvering av finally-klausulen\n"
"&gt;&gt;&gt; dividera(2, 0)\n"
"division med noll!\n"
"exekvering av sista klausul\n"
"&gt;&gt;&gt; divide(\"2\", \"1\")\n"
"exekvering av sista klausul\n"
"Traceback (senaste anropet senast):\n"
"  Fil \"<stdin>\", rad 1, i <module>\n"
"    dividera(\"2\", \"1\")\n"
"    ~~~~~~^^^^^^^^^^\n"
"  Fil \"<stdin>\", rad 3, i divide\n"
"    resultat = x / y\n"
"             ~~^~~\n"
"TypeError: operandtyp(er) som inte stöds för /: 'str' och 'str'"

msgid ""
"As you can see, the :keyword:`finally` clause is executed in any event.  "
"The :exc:`TypeError` raised by dividing two strings is not handled by the :"
"keyword:`except` clause and therefore re-raised after the :keyword:`!"
"finally` clause has been executed."
msgstr ""
"Som du kan se utförs :keyword:`finally`-satsen i vilket fall som helst.  "
"Det :exc:`TypeError` som uppstår när två strängar delas upp hanteras inte "
"av :keyword:`except`-satsen och uppstår därför igen efter att :keyword:`!"
"finally`-satsen har exekverats."

msgid ""
"In real world applications, the :keyword:`finally` clause is useful for "
"releasing external resources (such as files or network connections), "
"regardless of whether the use of the resource was successful."
msgstr ""
"I verkliga tillämpningar är klausulen :keyword:`finally` användbar för att "
"frigöra externa resurser (t.ex. filer eller nätverksanslutningar), oavsett "
"om användningen av resursen var framgångsrik eller inte."

msgid "Predefined Clean-up Actions"
msgstr "Fördefinierade saneringsåtgärder"

msgid ""
"Some objects define standard clean-up actions to be undertaken when the "
"object is no longer needed, regardless of whether or not the operation using "
"the object succeeded or failed. Look at the following example, which tries "
"to open a file and print its contents to the screen. ::"
msgstr ""
"Vissa objekt definierar standardstädningsåtgärder som ska vidtas när "
"objektet inte längre behövs, oavsett om operationen som använder objektet "
"lyckades eller misslyckades. Titta på följande exempel, som försöker öppna "
"en fil och skriva ut dess innehåll på skärmen. ::"

msgid ""
"for line in open(\"myfile.txt\"):\n"
"    print(line, end=\"\")"
msgstr ""
"för rad i open(\"minfil.txt\"):\n"
"    print(rad, slut=\"\")"

msgid ""
"The problem with this code is that it leaves the file open for an "
"indeterminate amount of time after this part of the code has finished "
"executing. This is not an issue in simple scripts, but can be a problem for "
"larger applications. The :keyword:`with` statement allows objects like files "
"to be used in a way that ensures they are always cleaned up promptly and "
"correctly. ::"
msgstr ""
"Problemet med den här koden är att den lämnar filen öppen under en obestämd "
"tid efter att den här delen av koden har exekverats. Detta är inte ett "
"problem i enkla skript, men kan vara ett problem för större applikationer. "
"Med :keyword:`with` kan objekt som filer användas på ett sätt som "
"säkerställer att de alltid rensas upp snabbt och korrekt. ::"

msgid ""
"with open(\"myfile.txt\") as f:\n"
"    for line in f:\n"
"        print(line, end=\"\")"
msgstr ""
"med open(\"minfil.txt\") som f:\n"
"    för rad i f:\n"
"        print(rad, slut=\"\")"

msgid ""
"After the statement is executed, the file *f* is always closed, even if a "
"problem was encountered while processing the lines. Objects which, like "
"files, provide predefined clean-up actions will indicate this in their "
"documentation."
msgstr ""
"Efter att satsen har utförts stängs alltid filen *f*, även om det uppstod "
"ett problem under bearbetningen av raderna. Objekt som, i likhet med filer, "
"har fördefinierade rensningsåtgärder kommer att ange detta i sin "
"dokumentation."

msgid "Raising and Handling Multiple Unrelated Exceptions"
msgstr "Upphävande och hantering av flera orelaterade undantag"

msgid ""
"There are situations where it is necessary to report several exceptions that "
"have occurred. This is often the case in concurrency frameworks, when "
"several tasks may have failed in parallel, but there are also other use "
"cases where it is desirable to continue execution and collect multiple "
"errors rather than raise the first exception."
msgstr ""
"Det finns situationer där det är nödvändigt att rapportera flera undantag "
"som har inträffat. Detta är ofta fallet i ramverk för samtidighet, när flera "
"uppgifter kan ha misslyckats parallellt, men det finns också andra "
"användningsfall där det är önskvärt att fortsätta exekveringen och samla in "
"flera fel i stället för att lösa ut det första undantaget."

msgid ""
"The builtin :exc:`ExceptionGroup` wraps a list of exception instances so "
"that they can be raised together. It is an exception itself, so it can be "
"caught like any other exception. ::"
msgstr ""
"Den inbyggda :exc:`ExceptionGroup` omsluter en lista med undantagsinstanser "
"så att de kan tas upp tillsammans. Det är ett undantag i sig, så det kan "
"fångas som vilket annat undantag som helst. ::"

msgid ""
">>> def f():\n"
"...     excs = [OSError('error 1'), SystemError('error 2')]\n"
"...     raise ExceptionGroup('there were problems', excs)\n"
"...\n"
">>> f()\n"
"  + Exception Group Traceback (most recent call last):\n"
"  |   File \"<stdin>\", line 1, in <module>\n"
"  |     f()\n"
"  |     ~^^\n"
"  |   File \"<stdin>\", line 3, in f\n"
"  |     raise ExceptionGroup('there were problems', excs)\n"
"  | ExceptionGroup: there were problems (2 sub-exceptions)\n"
"  +-+---------------- 1 ----------------\n"
"    | OSError: error 1\n"
"    +---------------- 2 ----------------\n"
"    | SystemError: error 2\n"
"    +------------------------------------\n"
">>> try:\n"
"...     f()\n"
"... except Exception as e:\n"
"...     print(f'caught {type(e)}: e')\n"
"...\n"
"caught <class 'ExceptionGroup'>: e\n"
">>>"
msgstr ""
"&gt;&gt;&gt; def f():\n"
"... excs = [OSError('fel 1'), SystemError('fel 2')]\n"
"... raise ExceptionGroup(\"det fanns problem\", excs)\n"
"...\n"
"&gt;&gt;&gt; f()\n"
"  + Exception Group Återkoppling (senaste anropet senast):\n"
"  | Fil \"<stdin>\", rad 1, i <module>\n"
"  | f()\n"
"  | ~^^\n"
"  | Fil \"<stdin>\", rad 3, i f\n"
"  | raise ExceptionGroup('det fanns problem', excs)\n"
"  | ExceptionGroup: det fanns problem (2 underundantag)\n"
"  +-+---------------- 1 ----------------\n"
"    | OSError: fel 1\n"
"    +---------------- 2 ----------------\n"
"    | SystemError: fel 2\n"
"    +------------------------------------\n"
"&gt;&gt;&gt; försök:\n"
"... f()\n"
"... except Exception as e:\n"
"... print(f'fångade {type(e)}: e')\n"
"...\n"
"fångade <class 'ExceptionGroup'>: e\n"
"&gt;&gt;&gt"

msgid ""
"By using ``except*`` instead of ``except``, we can selectively handle only "
"the exceptions in the group that match a certain type. In the following "
"example, which shows a nested exception group, each ``except*`` clause "
"extracts from the group exceptions of a certain type while letting all other "
"exceptions propagate to other clauses and eventually to be reraised. ::"
msgstr ""
"Genom att använda ``except*`` istället för ``except`` kan vi selektivt "
"hantera endast de undantag i gruppen som matchar en viss typ. I följande "
"exempel, som visar en nästlad undantagsgrupp, extraherar varje ``except*``-"
"klausul undantag av en viss typ från gruppen medan alla andra undantag "
"sprids till andra klausuler och så småningom återkallas:"

msgid ""
">>> def f():\n"
"...     raise ExceptionGroup(\n"
"...         \"group1\",\n"
"...         [\n"
"...             OSError(1),\n"
"...             SystemError(2),\n"
"...             ExceptionGroup(\n"
"...                 \"group2\",\n"
"...                 [\n"
"...                     OSError(3),\n"
"...                     RecursionError(4)\n"
"...                 ]\n"
"...             )\n"
"...         ]\n"
"...     )\n"
"...\n"
">>> try:\n"
"...     f()\n"
"... except* OSError as e:\n"
"...     print(\"There were OSErrors\")\n"
"... except* SystemError as e:\n"
"...     print(\"There were SystemErrors\")\n"
"...\n"
"There were OSErrors\n"
"There were SystemErrors\n"
"  + Exception Group Traceback (most recent call last):\n"
"  |   File \"<stdin>\", line 2, in <module>\n"
"  |     f()\n"
"  |     ~^^\n"
"  |   File \"<stdin>\", line 2, in f\n"
"  |     raise ExceptionGroup(\n"
"  |     ...<12 lines>...\n"
"  |     )\n"
"  | ExceptionGroup: group1 (1 sub-exception)\n"
"  +-+---------------- 1 ----------------\n"
"    | ExceptionGroup: group2 (1 sub-exception)\n"
"    +-+---------------- 1 ----------------\n"
"      | RecursionError: 4\n"
"      +------------------------------------\n"
">>>"
msgstr ""
"&gt;&gt;&gt; def f():\n"
"... raise ExceptionGroup(\n"
"...         \"grupp1\",\n"
"...         [\n"
"...             OSError(1),\n"
"...             SystemError(2),\n"
"...             ExceptionGroup(\n"
"...                 \"group2\",\n"
"...                 [\n"
"...                     OSError(3),\n"
"...                     RecursionError(4)\n"
"...                 ]\n"
"...             )\n"
"...         ]\n"
"...     )\n"
"...\n"
"&gt;&gt;&gt; försök:\n"
"... f()\n"
"... except* OSError as e:\n"
"... print(\"Det fanns OSError\")\n"
"... except* SystemError as e:\n"
"... print(\"Det uppstod systemfel\")\n"
"...\n"
"Det fanns OSErrors\n"
"Det fanns systemfel\n"
"  + Exception Group Återkoppling (senaste anropet senast):\n"
"  | Fil \"<stdin>\", rad 2, i <module>\n"
"  | f()\n"
"  | ~^^\n"
"  | Fil \"<stdin>\", rad 2, i f\n"
"  | raise ExceptionGroup(\n"
"  | ...<12 lines>...\n"
"  | )\n"
"  | ExceptionGroup: group1 (1 underundantag)\n"
"  +-+---------------- 1 ----------------\n"
"    | ExceptionGroup: group2 (1 underundantag)\n"
"    +-+---------------- 1 ----------------\n"
"      | RecursionError: 4\n"
"      +------------------------------------\n"
"&gt;&gt;&gt"

msgid ""
"Note that the exceptions nested in an exception group must be instances, not "
"types. This is because in practice the exceptions would typically be ones "
"that have already been raised and caught by the program, along the following "
"pattern::"
msgstr ""
"Observera att undantagen i en undantagsgrupp måste vara instanser, inte "
"typer. Detta beror på att undantagen i praktiken vanligtvis är sådana som "
"redan har tagits upp och fångats upp av programmet, enligt följande mönster::"

msgid ""
">>> excs = []\n"
"... for test in tests:\n"
"...     try:\n"
"...         test.run()\n"
"...     except Exception as e:\n"
"...         excs.append(e)\n"
"...\n"
">>> if excs:\n"
"...    raise ExceptionGroup(\"Test Failures\", excs)\n"
"..."
msgstr ""
">>> excs = []\n"
"... för test i tester:\n"
"... försök:\n"
"... test.run()\n"
"... except Exception as e:\n"
"... excs.append(e)\n"
"...\n"
">>> om excs:\n"
"... raise ExceptionGroup(\"Test misslyckades\", excs)\n"
"..."

msgid "Enriching Exceptions with Notes"
msgstr "Berika undantag med anteckningar"

msgid ""
"When an exception is created in order to be raised, it is usually "
"initialized with information that describes the error that has occurred. "
"There are cases where it is useful to add information after the exception "
"was caught. For this purpose, exceptions have a method ``add_note(note)`` "
"that accepts a string and adds it to the exception's notes list. The "
"standard traceback rendering includes all notes, in the order they were "
"added, after the exception. ::"
msgstr ""
"När ett undantag skapas för att fångas upp initialiseras det vanligtvis med "
"information som beskriver det fel som har inträffat. Det finns fall där det "
"är användbart att lägga till information efter att undantaget har fångats. "
"För detta ändamål har undantag en metod ``add_note(note)`` som accepterar en "
"sträng och lägger till den i undantagets anteckningslista. "
"Standardåtergivningen av spårningen innehåller alla anteckningar, i den "
"ordning de lades till, efter undantaget. ::"

msgid ""
">>> try:\n"
"...     raise TypeError('bad type')\n"
"... except Exception as e:\n"
"...     e.add_note('Add some information')\n"
"...     e.add_note('Add some more information')\n"
"...     raise\n"
"...\n"
"Traceback (most recent call last):\n"
"  File \"<stdin>\", line 2, in <module>\n"
"    raise TypeError('bad type')\n"
"TypeError: bad type\n"
"Add some information\n"
"Add some more information\n"
">>>"
msgstr ""
"&gt;&gt;&gt; försök:\n"
"... raise TypeError(\"dålig typ\")\n"
"... except Exception as e:\n"
"... e.add_note('Lägg till lite information')\n"
"... e.add_note('Lägg till lite mer information')\n"
"... raise\n"
"...\n"
"Traceback (senaste anropet senast):\n"
"  Fil \"<stdin>\", rad 2, i <module>\n"
"    raise TypeError(\"dålig typ\")\n"
"TypeError: dålig typ\n"
"Lägg till lite information\n"
"Lägg till lite mer information\n"
"&gt;&gt;&gt"

msgid ""
"For example, when collecting exceptions into an exception group, we may want "
"to add context information for the individual errors. In the following each "
"exception in the group has a note indicating when this error has occurred. ::"
msgstr ""
"När vi t.ex. samlar undantag i en undantagsgrupp kan vi vilja lägga till "
"kontextinformation för de enskilda felen. I det följande har varje undantag "
"i gruppen en anteckning som anger när detta fel har inträffat. ::"

msgid ""
">>> def f():\n"
"...     raise OSError('operation failed')\n"
"...\n"
">>> excs = []\n"
">>> for i in range(3):\n"
"...     try:\n"
"...         f()\n"
"...     except Exception as e:\n"
"...         e.add_note(f'Happened in Iteration {i+1}')\n"
"...         excs.append(e)\n"
"...\n"
">>> raise ExceptionGroup('We have some problems', excs)\n"
"  + Exception Group Traceback (most recent call last):\n"
"  |   File \"<stdin>\", line 1, in <module>\n"
"  |     raise ExceptionGroup('We have some problems', excs)\n"
"  | ExceptionGroup: We have some problems (3 sub-exceptions)\n"
"  +-+---------------- 1 ----------------\n"
"    | Traceback (most recent call last):\n"
"    |   File \"<stdin>\", line 3, in <module>\n"
"    |     f()\n"
"    |     ~^^\n"
"    |   File \"<stdin>\", line 2, in f\n"
"    |     raise OSError('operation failed')\n"
"    | OSError: operation failed\n"
"    | Happened in Iteration 1\n"
"    +---------------- 2 ----------------\n"
"    | Traceback (most recent call last):\n"
"    |   File \"<stdin>\", line 3, in <module>\n"
"    |     f()\n"
"    |     ~^^\n"
"    |   File \"<stdin>\", line 2, in f\n"
"    |     raise OSError('operation failed')\n"
"    | OSError: operation failed\n"
"    | Happened in Iteration 2\n"
"    +---------------- 3 ----------------\n"
"    | Traceback (most recent call last):\n"
"    |   File \"<stdin>\", line 3, in <module>\n"
"    |     f()\n"
"    |     ~^^\n"
"    |   File \"<stdin>\", line 2, in f\n"
"    |     raise OSError('operation failed')\n"
"    | OSError: operation failed\n"
"    | Happened in Iteration 3\n"
"    +------------------------------------\n"
">>>"
msgstr ""
"&gt;&gt;&gt; def f():\n"
"... raise OSError(\"operationen misslyckades\")\n"
"...\n"
"&gt;&gt;&gt; excs = []\n"
"&gt;&gt;&gt; för i i intervall(3):\n"
"... försök:\n"
"... f()\n"
"... except Exception as e:\n"
"... e.add_note(f'Skedde i iteration {i+1}')\n"
"... excs.append(e)\n"
"...\n"
"&gt;&gt;&gt; raise ExceptionGroup('Vi har några problem', excs)\n"
"  + Exception Group Traceback (senaste anropet senast):\n"
"  | Fil \"<stdin>\", rad 1, i <module>\n"
"  | raise ExceptionGroup('Vi har några problem', excs)\n"
"  | ExceptionGroup: Vi har några problem (3 underundantag)\n"
"  +-+---------------- 1 ----------------\n"
"    | Traceback (senaste anropet senast):\n"
"    | Fil \"<stdin>\", rad 3, i <module>\n"
"    | f()\n"
"    | ~^^\n"
"    | Fil \"<stdin>\", rad 2, i f\n"
"    | raise OSError('operationen misslyckades')\n"
"    | OSError: operationen misslyckades\n"
"    | Hände i iteration 1\n"
"    +---------------- 2 ----------------\n"
"    | Traceback (senaste anropet senast):\n"
"    | Fil \"<stdin>\", rad 3, i <module>\n"
"    | f()\n"
"    | ~^^\n"
"    | Fil \"<stdin>\", rad 2, i f\n"
"    | raise OSError('operationen misslyckades')\n"
"    | OSError: operationen misslyckades\n"
"    | Hände i iteration 2\n"
"    +---------------- 3 ----------------\n"
"    | Traceback (senaste anropet senast):\n"
"    | Fil \"<stdin>\", rad 3, i <module>\n"
"    | f()\n"
"    | ~^^\n"
"    | Fil \"<stdin>\", rad 2, i f\n"
"    | raise OSError('operationen misslyckades')\n"
"    | OSError: operationen misslyckades\n"
"    | Hände i iteration 3\n"
"    +------------------------------------\n"
"&gt;&gt;&gt"
